Traceback (most recent call last):
  File "/root/.pyenv/versions/3.9.5/bin/uvicorn", line 8, in <module>
    sys.exit(main())
  File "/root/.pyenv/versions/3.9.5/lib/python3.9/site-packages/click/core.py", line 1157, in __call__
    return self.main(*args, **kwargs)
  File "/root/.pyenv/versions/3.9.5/lib/python3.9/site-packages/click/core.py", line 1078, in main
    rv = self.invoke(ctx)
  File "/root/.pyenv/versions/3.9.5/lib/python3.9/site-packages/click/core.py", line 1434, in invoke
    return ctx.invoke(self.callback, **ctx.params)
  File "/root/.pyenv/versions/3.9.5/lib/python3.9/site-packages/click/core.py", line 783, in invoke
    return __callback(*args, **kwargs)
  File "/root/.pyenv/versions/3.9.5/lib/python3.9/site-packages/uvicorn/main.py", line 416, in main
    run(
  File "/root/.pyenv/versions/3.9.5/lib/python3.9/site-packages/uvicorn/main.py", line 587, in run
    server.run()
  File "/root/.pyenv/versions/3.9.5/lib/python3.9/site-packages/uvicorn/server.py", line 61, in run
    return asyncio.run(self.serve(sockets=sockets))
  File "/root/.pyenv/versions/3.9.5/lib/python3.9/asyncio/runners.py", line 44, in run
    return loop.run_until_complete(main)
  File "/root/.pyenv/versions/3.9.5/lib/python3.9/asyncio/base_events.py", line 642, in run_until_complete
    return future.result()
  File "/root/.pyenv/versions/3.9.5/lib/python3.9/site-packages/uvicorn/server.py", line 68, in serve
    config.load()
  File "/root/.pyenv/versions/3.9.5/lib/python3.9/site-packages/uvicorn/config.py", line 467, in load
    self.loaded_app = import_from_string(self.app)
  File "/root/.pyenv/versions/3.9.5/lib/python3.9/site-packages/uvicorn/importer.py", line 24, in import_from_string
    raise exc from None
  File "/root/.pyenv/versions/3.9.5/lib/python3.9/site-packages/uvicorn/importer.py", line 21, in import_from_string
    module = importlib.import_module(module_str)
  File "/root/.pyenv/versions/3.9.5/lib/python3.9/importlib/__init__.py", line 127, in import_module
    return _bootstrap._gcd_import(name[level:], package, level)
  File "<frozen importlib._bootstrap>", line 1030, in _gcd_import
  File "<frozen importlib._bootstrap>", line 1007, in _find_and_load
  File "<frozen importlib._bootstrap>", line 972, in _find_and_load_unlocked
  File "<frozen importlib._bootstrap>", line 228, in _call_with_frames_removed
  File "<frozen importlib._bootstrap>", line 1030, in _gcd_import
  File "<frozen importlib._bootstrap>", line 1007, in _find_and_load
  File "<frozen importlib._bootstrap>", line 984, in _find_and_load_unlocked
ModuleNotFoundError: No module named 'server'
Traceback (most recent call last):
  File "/root/.pyenv/versions/3.9.5/lib/python3.9/runpy.py", line 197, in _run_module_as_main
    return _run_code(code, main_globals, None,
  File "/root/.pyenv/versions/3.9.5/lib/python3.9/runpy.py", line 87, in _run_code
    exec(code, run_globals)
  File "/root/.pyenv/versions/3.9.5/lib/python3.9/http/server.py", line 1289, in <module>
    test(
  File "/root/.pyenv/versions/3.9.5/lib/python3.9/http/server.py", line 1244, in test
    with ServerClass(addr, HandlerClass) as httpd:
  File "/root/.pyenv/versions/3.9.5/lib/python3.9/socketserver.py", line 452, in __init__
    self.server_bind()
  File "/root/.pyenv/versions/3.9.5/lib/python3.9/http/server.py", line 1287, in server_bind
    return super().server_bind()
  File "/root/.pyenv/versions/3.9.5/lib/python3.9/http/server.py", line 138, in server_bind
    socketserver.TCPServer.server_bind(self)
  File "/root/.pyenv/versions/3.9.5/lib/python3.9/socketserver.py", line 466, in server_bind
    self.socket.bind(self.server_address)
OSError: [Errno 98] Address already in use
Traceback (most recent call last):
  File "/root/.pyenv/versions/3.9.5/bin/uvicorn", line 8, in <module>
    sys.exit(main())
  File "/root/.pyenv/versions/3.9.5/lib/python3.9/site-packages/click/core.py", line 1157, in __call__
    return self.main(*args, **kwargs)
  File "/root/.pyenv/versions/3.9.5/lib/python3.9/site-packages/click/core.py", line 1078, in main
    rv = self.invoke(ctx)
  File "/root/.pyenv/versions/3.9.5/lib/python3.9/site-packages/click/core.py", line 1434, in invoke
    return ctx.invoke(self.callback, **ctx.params)
  File "/root/.pyenv/versions/3.9.5/lib/python3.9/site-packages/click/core.py", line 783, in invoke
    return __callback(*args, **kwargs)
  File "/root/.pyenv/versions/3.9.5/lib/python3.9/site-packages/uvicorn/main.py", line 416, in main
    run(
  File "/root/.pyenv/versions/3.9.5/lib/python3.9/site-packages/uvicorn/main.py", line 587, in run
    server.run()
  File "/root/.pyenv/versions/3.9.5/lib/python3.9/site-packages/uvicorn/server.py", line 61, in run
    return asyncio.run(self.serve(sockets=sockets))
  File "/root/.pyenv/versions/3.9.5/lib/python3.9/asyncio/runners.py", line 44, in run
    return loop.run_until_complete(main)
  File "/root/.pyenv/versions/3.9.5/lib/python3.9/asyncio/base_events.py", line 642, in run_until_complete
    return future.result()
  File "/root/.pyenv/versions/3.9.5/lib/python3.9/site-packages/uvicorn/server.py", line 68, in serve
    config.load()
  File "/root/.pyenv/versions/3.9.5/lib/python3.9/site-packages/uvicorn/config.py", line 467, in load
    self.loaded_app = import_from_string(self.app)
  File "/root/.pyenv/versions/3.9.5/lib/python3.9/site-packages/uvicorn/importer.py", line 24, in import_from_string
    raise exc from None
  File "/root/.pyenv/versions/3.9.5/lib/python3.9/site-packages/uvicorn/importer.py", line 21, in import_from_string
    module = importlib.import_module(module_str)
  File "/root/.pyenv/versions/3.9.5/lib/python3.9/importlib/__init__.py", line 127, in import_module
    return _bootstrap._gcd_import(name[level:], package, level)
  File "<frozen importlib._bootstrap>", line 1030, in _gcd_import
  File "<frozen importlib._bootstrap>", line 1007, in _find_and_load
  File "<frozen importlib._bootstrap>", line 972, in _find_and_load_unlocked
  File "<frozen importlib._bootstrap>", line 228, in _call_with_frames_removed
  File "<frozen importlib._bootstrap>", line 1030, in _gcd_import
  File "<frozen importlib._bootstrap>", line 1007, in _find_and_load
  File "<frozen importlib._bootstrap>", line 984, in _find_and_load_unlocked
ModuleNotFoundError: No module named 'server'
172.17.0.1 - - [24/Dec/2023 13:07:56] code 404, message File not found
172.17.0.1 - - [24/Dec/2023 13:07:56] "GET /utils/function.js HTTP/1.1" 404 -
172.17.0.1 - - [24/Dec/2023 13:07:58] code 404, message File not found
172.17.0.1 - - [24/Dec/2023 13:07:58] "GET /utils/function.js HTTP/1.1" 404 -
172.17.0.1 - - [24/Dec/2023 13:07:58] code 404, message File not found
172.17.0.1 - - [24/Dec/2023 13:07:58] "GET /utils/function.js HTTP/1.1" 404 -
172.17.0.1 - - [24/Dec/2023 13:07:58] code 404, message File not found
172.17.0.1 - - [24/Dec/2023 13:07:58] "GET /utils/function.js HTTP/1.1" 404 -
172.17.0.1 - - [24/Dec/2023 13:08:00] code 404, message File not found
172.17.0.1 - - [24/Dec/2023 13:08:00] "GET / HTTP/1.1" 404 -
Traceback (most recent call last):
  File "/root/.pyenv/versions/3.9.5/bin/uvicorn", line 8, in <module>
    sys.exit(main())
  File "/root/.pyenv/versions/3.9.5/lib/python3.9/site-packages/click/core.py", line 1157, in __call__
    return self.main(*args, **kwargs)
  File "/root/.pyenv/versions/3.9.5/lib/python3.9/site-packages/click/core.py", line 1078, in main
    rv = self.invoke(ctx)
  File "/root/.pyenv/versions/3.9.5/lib/python3.9/site-packages/click/core.py", line 1434, in invoke
    return ctx.invoke(self.callback, **ctx.params)
  File "/root/.pyenv/versions/3.9.5/lib/python3.9/site-packages/click/core.py", line 783, in invoke
    return __callback(*args, **kwargs)
  File "/root/.pyenv/versions/3.9.5/lib/python3.9/site-packages/uvicorn/main.py", line 416, in main
    run(
  File "/root/.pyenv/versions/3.9.5/lib/python3.9/site-packages/uvicorn/main.py", line 587, in run
    server.run()
  File "/root/.pyenv/versions/3.9.5/lib/python3.9/site-packages/uvicorn/server.py", line 61, in run
    return asyncio.run(self.serve(sockets=sockets))
  File "/root/.pyenv/versions/3.9.5/lib/python3.9/asyncio/runners.py", line 44, in run
    return loop.run_until_complete(main)
  File "/root/.pyenv/versions/3.9.5/lib/python3.9/asyncio/base_events.py", line 642, in run_until_complete
    return future.result()
  File "/root/.pyenv/versions/3.9.5/lib/python3.9/site-packages/uvicorn/server.py", line 68, in serve
    config.load()
  File "/root/.pyenv/versions/3.9.5/lib/python3.9/site-packages/uvicorn/config.py", line 467, in load
    self.loaded_app = import_from_string(self.app)
  File "/root/.pyenv/versions/3.9.5/lib/python3.9/site-packages/uvicorn/importer.py", line 24, in import_from_string
    raise exc from None
  File "/root/.pyenv/versions/3.9.5/lib/python3.9/site-packages/uvicorn/importer.py", line 21, in import_from_string
    module = importlib.import_module(module_str)
  File "/root/.pyenv/versions/3.9.5/lib/python3.9/importlib/__init__.py", line 127, in import_module
    return _bootstrap._gcd_import(name[level:], package, level)
  File "<frozen importlib._bootstrap>", line 1030, in _gcd_import
  File "<frozen importlib._bootstrap>", line 1007, in _find_and_load
  File "<frozen importlib._bootstrap>", line 972, in _find_and_load_unlocked
  File "<frozen importlib._bootstrap>", line 228, in _call_with_frames_removed
  File "<frozen importlib._bootstrap>", line 1030, in _gcd_import
  File "<frozen importlib._bootstrap>", line 1007, in _find_and_load
  File "<frozen importlib._bootstrap>", line 984, in _find_and_load_unlocked
ModuleNotFoundError: No module named 'server'
172.17.0.1 - - [24/Dec/2023 13:10:58] code 404, message File not found
172.17.0.1 - - [24/Dec/2023 13:10:58] "GET / HTTP/1.1" 404 -
172.17.0.1 - - [24/Dec/2023 13:10:59] code 404, message File not found
172.17.0.1 - - [24/Dec/2023 13:10:59] "GET / HTTP/1.1" 404 -
172.17.0.1 - - [24/Dec/2023 13:11:00] code 404, message File not found
172.17.0.1 - - [24/Dec/2023 13:11:00] "GET / HTTP/1.1" 404 -
172.17.0.1 - - [24/Dec/2023 13:11:00] code 404, message File not found
172.17.0.1 - - [24/Dec/2023 13:11:00] "GET / HTTP/1.1" 404 -
172.17.0.1 - - [24/Dec/2023 13:11:00] code 404, message File not found
172.17.0.1 - - [24/Dec/2023 13:11:00] "GET / HTTP/1.1" 404 -
172.17.0.1 - - [24/Dec/2023 13:11:17] code 404, message File not found
172.17.0.1 - - [24/Dec/2023 13:11:17] "GET / HTTP/1.1" 404 -
172.17.0.1 - - [24/Dec/2023 13:12:07] code 404, message File not found
172.17.0.1 - - [24/Dec/2023 13:12:07] "GET / HTTP/1.1" 404 -
172.17.0.1 - - [24/Dec/2023 13:12:07] code 404, message File not found
172.17.0.1 - - [24/Dec/2023 13:12:07] "GET / HTTP/1.1" 404 -
Traceback (most recent call last):
  File "/root/.pyenv/versions/3.9.5/lib/python3.9/runpy.py", line 197, in _run_module_as_main
    return _run_code(code, main_globals, None,
  File "/root/.pyenv/versions/3.9.5/lib/python3.9/runpy.py", line 87, in _run_code
    exec(code, run_globals)
  File "/root/.pyenv/versions/3.9.5/lib/python3.9/http/server.py", line 1289, in <module>
    test(
  File "/root/.pyenv/versions/3.9.5/lib/python3.9/http/server.py", line 1244, in test
    with ServerClass(addr, HandlerClass) as httpd:
  File "/root/.pyenv/versions/3.9.5/lib/python3.9/socketserver.py", line 452, in __init__
    self.server_bind()
  File "/root/.pyenv/versions/3.9.5/lib/python3.9/http/server.py", line 1287, in server_bind
    return super().server_bind()
  File "/root/.pyenv/versions/3.9.5/lib/python3.9/http/server.py", line 138, in server_bind
    socketserver.TCPServer.server_bind(self)
  File "/root/.pyenv/versions/3.9.5/lib/python3.9/socketserver.py", line 466, in server_bind
    self.socket.bind(self.server_address)
OSError: [Errno 98] Address already in use
172.17.0.1 - - [24/Dec/2023 13:12:18] code 404, message File not found
172.17.0.1 - - [24/Dec/2023 13:12:18] "GET / HTTP/1.1" 404 -
172.17.0.1 - - [24/Dec/2023 13:12:18] code 404, message File not found
172.17.0.1 - - [24/Dec/2023 13:12:18] "GET / HTTP/1.1" 404 -
172.17.0.1 - - [24/Dec/2023 13:12:19] code 404, message File not found
172.17.0.1 - - [24/Dec/2023 13:12:19] "GET / HTTP/1.1" 404 -
172.17.0.1 - - [24/Dec/2023 13:12:19] code 404, message File not found
172.17.0.1 - - [24/Dec/2023 13:12:19] "GET / HTTP/1.1" 404 -
172.17.0.1 - - [24/Dec/2023 13:12:23] code 404, message File not found
172.17.0.1 - - [24/Dec/2023 13:12:23] "GET / HTTP/1.1" 404 -
172.17.0.1 - - [24/Dec/2023 13:12:23] code 404, message File not found
172.17.0.1 - - [24/Dec/2023 13:12:23] "GET / HTTP/1.1" 404 -
172.17.0.1 - - [24/Dec/2023 13:12:23] code 404, message File not found
172.17.0.1 - - [24/Dec/2023 13:12:23] "GET / HTTP/1.1" 404 -
172.17.0.1 - - [24/Dec/2023 13:12:23] code 404, message File not found
172.17.0.1 - - [24/Dec/2023 13:12:23] "GET / HTTP/1.1" 404 -
172.17.0.1 - - [24/Dec/2023 13:12:24] code 404, message File not found
172.17.0.1 - - [24/Dec/2023 13:12:24] "GET / HTTP/1.1" 404 -
172.17.0.1 - - [24/Dec/2023 13:12:24] code 404, message File not found
172.17.0.1 - - [24/Dec/2023 13:12:24] "GET / HTTP/1.1" 404 -
172.17.0.1 - - [24/Dec/2023 13:12:24] code 404, message File not found
172.17.0.1 - - [24/Dec/2023 13:12:24] "GET / HTTP/1.1" 404 -
172.17.0.1 - - [24/Dec/2023 13:12:25] code 404, message File not found
172.17.0.1 - - [24/Dec/2023 13:12:25] "GET / HTTP/1.1" 404 -
172.17.0.1 - - [24/Dec/2023 13:13:05] code 404, message File not found
172.17.0.1 - - [24/Dec/2023 13:13:05] "GET / HTTP/1.1" 404 -
172.17.0.1 - - [24/Dec/2023 13:17:08] code 404, message File not found
172.17.0.1 - - [24/Dec/2023 13:17:08] "GET / HTTP/1.1" 404 -
Traceback (most recent call last):
  File "/root/.pyenv/versions/3.9.5/bin/uvicorn", line 8, in <module>
    sys.exit(main())
  File "/root/.pyenv/versions/3.9.5/lib/python3.9/site-packages/click/core.py", line 1157, in __call__
    return self.main(*args, **kwargs)
  File "/root/.pyenv/versions/3.9.5/lib/python3.9/site-packages/click/core.py", line 1078, in main
    rv = self.invoke(ctx)
  File "/root/.pyenv/versions/3.9.5/lib/python3.9/site-packages/click/core.py", line 1434, in invoke
    return ctx.invoke(self.callback, **ctx.params)
  File "/root/.pyenv/versions/3.9.5/lib/python3.9/site-packages/click/core.py", line 783, in invoke
    return __callback(*args, **kwargs)
  File "/root/.pyenv/versions/3.9.5/lib/python3.9/site-packages/uvicorn/main.py", line 416, in main
    run(
  File "/root/.pyenv/versions/3.9.5/lib/python3.9/site-packages/uvicorn/main.py", line 587, in run
    server.run()
  File "/root/.pyenv/versions/3.9.5/lib/python3.9/site-packages/uvicorn/server.py", line 61, in run
    return asyncio.run(self.serve(sockets=sockets))
  File "/root/.pyenv/versions/3.9.5/lib/python3.9/asyncio/runners.py", line 44, in run
    return loop.run_until_complete(main)
  File "/root/.pyenv/versions/3.9.5/lib/python3.9/asyncio/base_events.py", line 642, in run_until_complete
    return future.result()
  File "/root/.pyenv/versions/3.9.5/lib/python3.9/site-packages/uvicorn/server.py", line 68, in serve
    config.load()
  File "/root/.pyenv/versions/3.9.5/lib/python3.9/site-packages/uvicorn/config.py", line 467, in load
    self.loaded_app = import_from_string(self.app)
  File "/root/.pyenv/versions/3.9.5/lib/python3.9/site-packages/uvicorn/importer.py", line 24, in import_from_string
    raise exc from None
  File "/root/.pyenv/versions/3.9.5/lib/python3.9/site-packages/uvicorn/importer.py", line 21, in import_from_string
    module = importlib.import_module(module_str)
  File "/root/.pyenv/versions/3.9.5/lib/python3.9/importlib/__init__.py", line 127, in import_module
    return _bootstrap._gcd_import(name[level:], package, level)
  File "<frozen importlib._bootstrap>", line 1030, in _gcd_import
  File "<frozen importlib._bootstrap>", line 1007, in _find_and_load
  File "<frozen importlib._bootstrap>", line 972, in _find_and_load_unlocked
  File "<frozen importlib._bootstrap>", line 228, in _call_with_frames_removed
  File "<frozen importlib._bootstrap>", line 1030, in _gcd_import
  File "<frozen importlib._bootstrap>", line 1007, in _find_and_load
  File "<frozen importlib._bootstrap>", line 984, in _find_and_load_unlocked
ModuleNotFoundError: No module named 'server'
INFO:     Will watch for changes in these directories: ['/workspace/codeconnection/server']
INFO:     Uvicorn running on http://0.0.0.0:8088 (Press CTRL+C to quit)
INFO:     Started reloader process [58619] using StatReload
Process SpawnProcess-1:
Traceback (most recent call last):
  File "/root/.pyenv/versions/3.9.5/lib/python3.9/multiprocessing/process.py", line 315, in _bootstrap
    self.run()
  File "/root/.pyenv/versions/3.9.5/lib/python3.9/multiprocessing/process.py", line 108, in run
    self._target(*self._args, **self._kwargs)
  File "/root/.pyenv/versions/3.9.5/lib/python3.9/site-packages/uvicorn/_subprocess.py", line 76, in subprocess_started
    target(sockets=sockets)
  File "/root/.pyenv/versions/3.9.5/lib/python3.9/site-packages/uvicorn/server.py", line 61, in run
    return asyncio.run(self.serve(sockets=sockets))
  File "/root/.pyenv/versions/3.9.5/lib/python3.9/asyncio/runners.py", line 44, in run
    return loop.run_until_complete(main)
  File "/root/.pyenv/versions/3.9.5/lib/python3.9/asyncio/base_events.py", line 642, in run_until_complete
    return future.result()
  File "/root/.pyenv/versions/3.9.5/lib/python3.9/site-packages/uvicorn/server.py", line 68, in serve
    config.load()
  File "/root/.pyenv/versions/3.9.5/lib/python3.9/site-packages/uvicorn/config.py", line 467, in load
    self.loaded_app = import_from_string(self.app)
  File "/root/.pyenv/versions/3.9.5/lib/python3.9/site-packages/uvicorn/importer.py", line 24, in import_from_string
    raise exc from None
  File "/root/.pyenv/versions/3.9.5/lib/python3.9/site-packages/uvicorn/importer.py", line 21, in import_from_string
    module = importlib.import_module(module_str)
  File "/root/.pyenv/versions/3.9.5/lib/python3.9/importlib/__init__.py", line 127, in import_module
    return _bootstrap._gcd_import(name[level:], package, level)
  File "<frozen importlib._bootstrap>", line 1030, in _gcd_import
  File "<frozen importlib._bootstrap>", line 1007, in _find_and_load
  File "<frozen importlib._bootstrap>", line 972, in _find_and_load_unlocked
  File "<frozen importlib._bootstrap>", line 228, in _call_with_frames_removed
  File "<frozen importlib._bootstrap>", line 1030, in _gcd_import
  File "<frozen importlib._bootstrap>", line 1007, in _find_and_load
  File "<frozen importlib._bootstrap>", line 984, in _find_and_load_unlocked
ModuleNotFoundError: No module named 'server'
172.17.0.1 - - [24/Dec/2023 13:21:26] code 404, message File not found
172.17.0.1 - - [24/Dec/2023 13:21:26] "GET /utils/function.js HTTP/1.1" 404 -
172.17.0.1 - - [24/Dec/2023 13:21:36] code 404, message File not found
172.17.0.1 - - [24/Dec/2023 13:21:36] "GET /utils/function.js HTTP/1.1" 404 -
172.17.0.1 - - [24/Dec/2023 13:21:36] code 404, message File not found
172.17.0.1 - - [24/Dec/2023 13:21:36] "GET /utils/function.js HTTP/1.1" 404 -
172.17.0.1 - - [24/Dec/2023 13:21:37] code 404, message File not found
172.17.0.1 - - [24/Dec/2023 13:21:37] "GET /utils/function.js HTTP/1.1" 404 -
172.17.0.1 - - [24/Dec/2023 13:22:16] code 404, message File not found
172.17.0.1 - - [24/Dec/2023 13:22:16] "GET /utils/function.js HTTP/1.1" 404 -
172.17.0.1 - - [24/Dec/2023 13:22:17] code 404, message File not found
172.17.0.1 - - [24/Dec/2023 13:22:17] "GET /utils/function.js HTTP/1.1" 404 -
172.17.0.1 - - [24/Dec/2023 13:22:17] code 404, message File not found
172.17.0.1 - - [24/Dec/2023 13:22:17] "GET /utils/function.js HTTP/1.1" 404 -
172.17.0.1 - - [24/Dec/2023 13:22:46] code 404, message File not found
172.17.0.1 - - [24/Dec/2023 13:22:46] "GET /utils/function.js HTTP/1.1" 404 -
172.17.0.1 - - [24/Dec/2023 13:22:47] code 404, message File not found
172.17.0.1 - - [24/Dec/2023 13:22:47] "GET /utils/function.js HTTP/1.1" 404 -
172.17.0.1 - - [24/Dec/2023 13:22:47] code 404, message File not found
172.17.0.1 - - [24/Dec/2023 13:22:47] "GET /utils/function.js HTTP/1.1" 404 -
172.17.0.1 - - [24/Dec/2023 13:22:48] code 404, message File not found
172.17.0.1 - - [24/Dec/2023 13:22:48] "GET /utils/function.js HTTP/1.1" 404 -
172.17.0.1 - - [24/Dec/2023 13:22:49] code 404, message File not found
172.17.0.1 - - [24/Dec/2023 13:22:49] "GET / HTTP/1.1" 404 -
